{
 "cells": [
  {
   "cell_type": "code",
   "execution_count": 13,
   "metadata": {},
   "outputs": [],
   "source": [
    "import tensorflow as tf\n",
    "import numpy as np"
   ]
  },
  {
   "cell_type": "code",
   "execution_count": 14,
   "metadata": {},
   "outputs": [],
   "source": [
    "W = tf.Variable([[1,2,3],[3,4,5]],dtype=tf.float32,name='weights')\n",
    "b = tf.Variable([[1,2,3]],dtype=tf.float32,name=\"biases\")"
   ]
  },
  {
   "cell_type": "code",
   "execution_count": 15,
   "metadata": {},
   "outputs": [],
   "source": [
    "init = tf.global_variables_initializer()"
   ]
  },
  {
   "cell_type": "code",
   "execution_count": 16,
   "metadata": {},
   "outputs": [],
   "source": [
    "saver = tf.train.Saver()"
   ]
  },
  {
   "cell_type": "code",
   "execution_count": 17,
   "metadata": {},
   "outputs": [
    {
     "name": "stdout",
     "output_type": "stream",
     "text": [
      "save_path: my_net/save_net.ckpt\n"
     ]
    }
   ],
   "source": [
    "with tf.Session() as sess:\n",
    "    sess.run(init)\n",
    "    saver_path = saver.save(sess,\"my_net/save_net.ckpt\")\n",
    "    print(\"save_path:\",saver_path)"
   ]
  },
  {
   "cell_type": "markdown",
   "metadata": {},
   "source": [
    "## restore variables \n",
    "### redefine the same shape and same type for your variables"
   ]
  },
  {
   "cell_type": "code",
   "execution_count": 18,
   "metadata": {},
   "outputs": [],
   "source": [
    "W = tf.Variable(np.arange(6).reshape((2,3)),dtype=tf.float32,name=\"weights\")\n",
    "b = tf.Variable(np.arange(3).reshape((1,3)),dtype=tf.float32,name=\"biases\")"
   ]
  },
  {
   "cell_type": "markdown",
   "metadata": {},
   "source": [
    "### not need init step"
   ]
  },
  {
   "cell_type": "code",
   "execution_count": 12,
   "metadata": {},
   "outputs": [
    {
     "name": "stdout",
     "output_type": "stream",
     "text": [
      "INFO:tensorflow:Restoring parameters from my_net/save_net.ckpt\n"
     ]
    },
    {
     "ename": "NotFoundError",
     "evalue": "Key biases not found in checkpoint\n\t [[Node: save_3/RestoreV2 = RestoreV2[dtypes=[DT_FLOAT, DT_FLOAT, DT_FLOAT, DT_FLOAT, DT_FLOAT, DT_FLOAT], _device=\"/job:localhost/replica:0/task:0/device:CPU:0\"](_arg_save_3/Const_0_0, save_3/RestoreV2/tensor_names, save_3/RestoreV2/shape_and_slices)]]\n\nCaused by op 'save_3/RestoreV2', defined at:\n  File \"/usr/local/Cellar/python/3.6.5/Frameworks/Python.framework/Versions/3.6/lib/python3.6/runpy.py\", line 193, in _run_module_as_main\n    \"__main__\", mod_spec)\n  File \"/usr/local/Cellar/python/3.6.5/Frameworks/Python.framework/Versions/3.6/lib/python3.6/runpy.py\", line 85, in _run_code\n    exec(code, run_globals)\n  File \"/usr/local/lib/python3.6/site-packages/ipykernel_launcher.py\", line 16, in <module>\n    app.launch_new_instance()\n  File \"/usr/local/lib/python3.6/site-packages/traitlets/config/application.py\", line 658, in launch_instance\n    app.start()\n  File \"/usr/local/lib/python3.6/site-packages/ipykernel/kernelapp.py\", line 486, in start\n    self.io_loop.start()\n  File \"/usr/local/lib/python3.6/site-packages/tornado/platform/asyncio.py\", line 127, in start\n    self.asyncio_loop.run_forever()\n  File \"/usr/local/Cellar/python/3.6.5/Frameworks/Python.framework/Versions/3.6/lib/python3.6/asyncio/base_events.py\", line 422, in run_forever\n    self._run_once()\n  File \"/usr/local/Cellar/python/3.6.5/Frameworks/Python.framework/Versions/3.6/lib/python3.6/asyncio/base_events.py\", line 1432, in _run_once\n    handle._run()\n  File \"/usr/local/Cellar/python/3.6.5/Frameworks/Python.framework/Versions/3.6/lib/python3.6/asyncio/events.py\", line 145, in _run\n    self._callback(*self._args)\n  File \"/usr/local/lib/python3.6/site-packages/tornado/platform/asyncio.py\", line 117, in _handle_events\n    handler_func(fileobj, events)\n  File \"/usr/local/lib/python3.6/site-packages/tornado/stack_context.py\", line 276, in null_wrapper\n    return fn(*args, **kwargs)\n  File \"/usr/local/lib/python3.6/site-packages/zmq/eventloop/zmqstream.py\", line 450, in _handle_events\n    self._handle_recv()\n  File \"/usr/local/lib/python3.6/site-packages/zmq/eventloop/zmqstream.py\", line 480, in _handle_recv\n    self._run_callback(callback, msg)\n  File \"/usr/local/lib/python3.6/site-packages/zmq/eventloop/zmqstream.py\", line 432, in _run_callback\n    callback(*args, **kwargs)\n  File \"/usr/local/lib/python3.6/site-packages/tornado/stack_context.py\", line 276, in null_wrapper\n    return fn(*args, **kwargs)\n  File \"/usr/local/lib/python3.6/site-packages/ipykernel/kernelbase.py\", line 283, in dispatcher\n    return self.dispatch_shell(stream, msg)\n  File \"/usr/local/lib/python3.6/site-packages/ipykernel/kernelbase.py\", line 233, in dispatch_shell\n    handler(stream, idents, msg)\n  File \"/usr/local/lib/python3.6/site-packages/ipykernel/kernelbase.py\", line 399, in execute_request\n    user_expressions, allow_stdin)\n  File \"/usr/local/lib/python3.6/site-packages/ipykernel/ipkernel.py\", line 208, in do_execute\n    res = shell.run_cell(code, store_history=store_history, silent=silent)\n  File \"/usr/local/lib/python3.6/site-packages/ipykernel/zmqshell.py\", line 537, in run_cell\n    return super(ZMQInteractiveShell, self).run_cell(*args, **kwargs)\n  File \"/usr/local/lib/python3.6/site-packages/IPython/core/interactiveshell.py\", line 2662, in run_cell\n    raw_cell, store_history, silent, shell_futures)\n  File \"/usr/local/lib/python3.6/site-packages/IPython/core/interactiveshell.py\", line 2785, in _run_cell\n    interactivity=interactivity, compiler=compiler, result=result)\n  File \"/usr/local/lib/python3.6/site-packages/IPython/core/interactiveshell.py\", line 2903, in run_ast_nodes\n    if self.run_code(code, result):\n  File \"/usr/local/lib/python3.6/site-packages/IPython/core/interactiveshell.py\", line 2963, in run_code\n    exec(code_obj, self.user_global_ns, self.user_ns)\n  File \"<ipython-input-12-8ef2c2dac44f>\", line 1, in <module>\n    saver = tf.train.Saver()\n  File \"/usr/local/lib/python3.6/site-packages/tensorflow/python/training/saver.py\", line 1284, in __init__\n    self.build()\n  File \"/usr/local/lib/python3.6/site-packages/tensorflow/python/training/saver.py\", line 1296, in build\n    self._build(self._filename, build_save=True, build_restore=True)\n  File \"/usr/local/lib/python3.6/site-packages/tensorflow/python/training/saver.py\", line 1333, in _build\n    build_save=build_save, build_restore=build_restore)\n  File \"/usr/local/lib/python3.6/site-packages/tensorflow/python/training/saver.py\", line 781, in _build_internal\n    restore_sequentially, reshape)\n  File \"/usr/local/lib/python3.6/site-packages/tensorflow/python/training/saver.py\", line 400, in _AddRestoreOps\n    restore_sequentially)\n  File \"/usr/local/lib/python3.6/site-packages/tensorflow/python/training/saver.py\", line 832, in bulk_restore\n    return io_ops.restore_v2(filename_tensor, names, slices, dtypes)\n  File \"/usr/local/lib/python3.6/site-packages/tensorflow/python/ops/gen_io_ops.py\", line 1463, in restore_v2\n    shape_and_slices=shape_and_slices, dtypes=dtypes, name=name)\n  File \"/usr/local/lib/python3.6/site-packages/tensorflow/python/framework/op_def_library.py\", line 787, in _apply_op_helper\n    op_def=op_def)\n  File \"/usr/local/lib/python3.6/site-packages/tensorflow/python/framework/ops.py\", line 3414, in create_op\n    op_def=op_def)\n  File \"/usr/local/lib/python3.6/site-packages/tensorflow/python/framework/ops.py\", line 1740, in __init__\n    self._traceback = self._graph._extract_stack()  # pylint: disable=protected-access\n\nNotFoundError (see above for traceback): Key biases not found in checkpoint\n\t [[Node: save_3/RestoreV2 = RestoreV2[dtypes=[DT_FLOAT, DT_FLOAT, DT_FLOAT, DT_FLOAT, DT_FLOAT, DT_FLOAT], _device=\"/job:localhost/replica:0/task:0/device:CPU:0\"](_arg_save_3/Const_0_0, save_3/RestoreV2/tensor_names, save_3/RestoreV2/shape_and_slices)]]\n",
     "output_type": "error",
     "traceback": [
      "\u001b[0;31m---------------------------------------------------------------------------\u001b[0m",
      "\u001b[0;31mNotFoundError\u001b[0m                             Traceback (most recent call last)",
      "\u001b[0;32m/usr/local/lib/python3.6/site-packages/tensorflow/python/client/session.py\u001b[0m in \u001b[0;36m_do_call\u001b[0;34m(self, fn, *args)\u001b[0m\n\u001b[1;32m   1321\u001b[0m     \u001b[0;32mtry\u001b[0m\u001b[0;34m:\u001b[0m\u001b[0;34m\u001b[0m\u001b[0m\n\u001b[0;32m-> 1322\u001b[0;31m       \u001b[0;32mreturn\u001b[0m \u001b[0mfn\u001b[0m\u001b[0;34m(\u001b[0m\u001b[0;34m*\u001b[0m\u001b[0margs\u001b[0m\u001b[0;34m)\u001b[0m\u001b[0;34m\u001b[0m\u001b[0m\n\u001b[0m\u001b[1;32m   1323\u001b[0m     \u001b[0;32mexcept\u001b[0m \u001b[0merrors\u001b[0m\u001b[0;34m.\u001b[0m\u001b[0mOpError\u001b[0m \u001b[0;32mas\u001b[0m \u001b[0me\u001b[0m\u001b[0;34m:\u001b[0m\u001b[0;34m\u001b[0m\u001b[0m\n",
      "\u001b[0;32m/usr/local/lib/python3.6/site-packages/tensorflow/python/client/session.py\u001b[0m in \u001b[0;36m_run_fn\u001b[0;34m(feed_dict, fetch_list, target_list, options, run_metadata)\u001b[0m\n\u001b[1;32m   1306\u001b[0m       return self._call_tf_sessionrun(\n\u001b[0;32m-> 1307\u001b[0;31m           options, feed_dict, fetch_list, target_list, run_metadata)\n\u001b[0m\u001b[1;32m   1308\u001b[0m \u001b[0;34m\u001b[0m\u001b[0m\n",
      "\u001b[0;32m/usr/local/lib/python3.6/site-packages/tensorflow/python/client/session.py\u001b[0m in \u001b[0;36m_call_tf_sessionrun\u001b[0;34m(self, options, feed_dict, fetch_list, target_list, run_metadata)\u001b[0m\n\u001b[1;32m   1408\u001b[0m           \u001b[0mself\u001b[0m\u001b[0;34m.\u001b[0m\u001b[0m_session\u001b[0m\u001b[0;34m,\u001b[0m \u001b[0moptions\u001b[0m\u001b[0;34m,\u001b[0m \u001b[0mfeed_dict\u001b[0m\u001b[0;34m,\u001b[0m \u001b[0mfetch_list\u001b[0m\u001b[0;34m,\u001b[0m \u001b[0mtarget_list\u001b[0m\u001b[0;34m,\u001b[0m\u001b[0;34m\u001b[0m\u001b[0m\n\u001b[0;32m-> 1409\u001b[0;31m           run_metadata)\n\u001b[0m\u001b[1;32m   1410\u001b[0m     \u001b[0;32melse\u001b[0m\u001b[0;34m:\u001b[0m\u001b[0;34m\u001b[0m\u001b[0m\n",
      "\u001b[0;31mNotFoundError\u001b[0m: Key biases not found in checkpoint\n\t [[Node: save_3/RestoreV2 = RestoreV2[dtypes=[DT_FLOAT, DT_FLOAT, DT_FLOAT, DT_FLOAT, DT_FLOAT, DT_FLOAT], _device=\"/job:localhost/replica:0/task:0/device:CPU:0\"](_arg_save_3/Const_0_0, save_3/RestoreV2/tensor_names, save_3/RestoreV2/shape_and_slices)]]",
      "\nDuring handling of the above exception, another exception occurred:\n",
      "\u001b[0;31mNotFoundError\u001b[0m                             Traceback (most recent call last)",
      "\u001b[0;32m<ipython-input-12-8ef2c2dac44f>\u001b[0m in \u001b[0;36m<module>\u001b[0;34m()\u001b[0m\n\u001b[1;32m      1\u001b[0m \u001b[0msaver\u001b[0m \u001b[0;34m=\u001b[0m \u001b[0mtf\u001b[0m\u001b[0;34m.\u001b[0m\u001b[0mtrain\u001b[0m\u001b[0;34m.\u001b[0m\u001b[0mSaver\u001b[0m\u001b[0;34m(\u001b[0m\u001b[0;34m)\u001b[0m\u001b[0;34m\u001b[0m\u001b[0m\n\u001b[1;32m      2\u001b[0m \u001b[0;32mwith\u001b[0m \u001b[0mtf\u001b[0m\u001b[0;34m.\u001b[0m\u001b[0mSession\u001b[0m\u001b[0;34m(\u001b[0m\u001b[0;34m)\u001b[0m \u001b[0;32mas\u001b[0m \u001b[0msession\u001b[0m\u001b[0;34m:\u001b[0m\u001b[0;34m\u001b[0m\u001b[0m\n\u001b[0;32m----> 3\u001b[0;31m     \u001b[0msaver\u001b[0m\u001b[0;34m.\u001b[0m\u001b[0mrestore\u001b[0m\u001b[0;34m(\u001b[0m\u001b[0msession\u001b[0m\u001b[0;34m,\u001b[0m\u001b[0;34m\"my_net/save_net.ckpt\"\u001b[0m\u001b[0;34m)\u001b[0m\u001b[0;34m\u001b[0m\u001b[0m\n\u001b[0m\u001b[1;32m      4\u001b[0m     \u001b[0mprint\u001b[0m\u001b[0;34m(\u001b[0m\u001b[0;34m'weights:'\u001b[0m\u001b[0;34m,\u001b[0m\u001b[0msession\u001b[0m\u001b[0;34m.\u001b[0m\u001b[0mrun\u001b[0m\u001b[0;34m(\u001b[0m\u001b[0mW\u001b[0m\u001b[0;34m)\u001b[0m\u001b[0;34m)\u001b[0m\u001b[0;34m\u001b[0m\u001b[0m\n\u001b[1;32m      5\u001b[0m     \u001b[0mprint\u001b[0m\u001b[0;34m(\u001b[0m\u001b[0;34m'biases:'\u001b[0m\u001b[0;34m,\u001b[0m\u001b[0msession\u001b[0m\u001b[0;34m,\u001b[0m\u001b[0mrun\u001b[0m\u001b[0;34m(\u001b[0m\u001b[0mb\u001b[0m\u001b[0;34m)\u001b[0m\u001b[0;34m)\u001b[0m\u001b[0;34m\u001b[0m\u001b[0m\n",
      "\u001b[0;32m/usr/local/lib/python3.6/site-packages/tensorflow/python/training/saver.py\u001b[0m in \u001b[0;36mrestore\u001b[0;34m(self, sess, save_path)\u001b[0m\n\u001b[1;32m   1766\u001b[0m         \u001b[0mshould_reraise\u001b[0m \u001b[0;34m=\u001b[0m \u001b[0;32mTrue\u001b[0m\u001b[0;34m\u001b[0m\u001b[0m\n\u001b[1;32m   1767\u001b[0m       \u001b[0;32mif\u001b[0m \u001b[0mshould_reraise\u001b[0m\u001b[0;34m:\u001b[0m\u001b[0;34m\u001b[0m\u001b[0m\n\u001b[0;32m-> 1768\u001b[0;31m         \u001b[0msix\u001b[0m\u001b[0;34m.\u001b[0m\u001b[0mreraise\u001b[0m\u001b[0;34m(\u001b[0m\u001b[0mexception_type\u001b[0m\u001b[0;34m,\u001b[0m \u001b[0mexception_value\u001b[0m\u001b[0;34m,\u001b[0m \u001b[0mexception_traceback\u001b[0m\u001b[0;34m)\u001b[0m\u001b[0;34m\u001b[0m\u001b[0m\n\u001b[0m\u001b[1;32m   1769\u001b[0m       \u001b[0;32mdel\u001b[0m \u001b[0mexception_traceback\u001b[0m  \u001b[0;31m# avoid reference cycles\u001b[0m\u001b[0;34m\u001b[0m\u001b[0m\n\u001b[1;32m   1770\u001b[0m \u001b[0;34m\u001b[0m\u001b[0m\n",
      "\u001b[0;32m/usr/local/lib/python3.6/site-packages/six.py\u001b[0m in \u001b[0;36mreraise\u001b[0;34m(tp, value, tb)\u001b[0m\n\u001b[1;32m    691\u001b[0m             \u001b[0;32mif\u001b[0m \u001b[0mvalue\u001b[0m\u001b[0;34m.\u001b[0m\u001b[0m__traceback__\u001b[0m \u001b[0;32mis\u001b[0m \u001b[0;32mnot\u001b[0m \u001b[0mtb\u001b[0m\u001b[0;34m:\u001b[0m\u001b[0;34m\u001b[0m\u001b[0m\n\u001b[1;32m    692\u001b[0m                 \u001b[0;32mraise\u001b[0m \u001b[0mvalue\u001b[0m\u001b[0;34m.\u001b[0m\u001b[0mwith_traceback\u001b[0m\u001b[0;34m(\u001b[0m\u001b[0mtb\u001b[0m\u001b[0;34m)\u001b[0m\u001b[0;34m\u001b[0m\u001b[0m\n\u001b[0;32m--> 693\u001b[0;31m             \u001b[0;32mraise\u001b[0m \u001b[0mvalue\u001b[0m\u001b[0;34m\u001b[0m\u001b[0m\n\u001b[0m\u001b[1;32m    694\u001b[0m         \u001b[0;32mfinally\u001b[0m\u001b[0;34m:\u001b[0m\u001b[0;34m\u001b[0m\u001b[0m\n\u001b[1;32m    695\u001b[0m             \u001b[0mvalue\u001b[0m \u001b[0;34m=\u001b[0m \u001b[0;32mNone\u001b[0m\u001b[0;34m\u001b[0m\u001b[0m\n",
      "\u001b[0;32m/usr/local/lib/python3.6/site-packages/tensorflow/python/training/saver.py\u001b[0m in \u001b[0;36mrestore\u001b[0;34m(self, sess, save_path)\u001b[0m\n\u001b[1;32m   1750\u001b[0m       \u001b[0;32melse\u001b[0m\u001b[0;34m:\u001b[0m\u001b[0;34m\u001b[0m\u001b[0m\n\u001b[1;32m   1751\u001b[0m         sess.run(self.saver_def.restore_op_name,\n\u001b[0;32m-> 1752\u001b[0;31m                  {self.saver_def.filename_tensor_name: save_path})\n\u001b[0m\u001b[1;32m   1753\u001b[0m     \u001b[0;32mexcept\u001b[0m \u001b[0merrors\u001b[0m\u001b[0;34m.\u001b[0m\u001b[0mNotFoundError\u001b[0m\u001b[0;34m:\u001b[0m\u001b[0;34m\u001b[0m\u001b[0m\n\u001b[1;32m   1754\u001b[0m       \u001b[0mexception_type\u001b[0m\u001b[0;34m,\u001b[0m \u001b[0mexception_value\u001b[0m\u001b[0;34m,\u001b[0m \u001b[0mexception_traceback\u001b[0m \u001b[0;34m=\u001b[0m \u001b[0msys\u001b[0m\u001b[0;34m.\u001b[0m\u001b[0mexc_info\u001b[0m\u001b[0;34m(\u001b[0m\u001b[0;34m)\u001b[0m\u001b[0;34m\u001b[0m\u001b[0m\n",
      "\u001b[0;32m/usr/local/lib/python3.6/site-packages/tensorflow/python/client/session.py\u001b[0m in \u001b[0;36mrun\u001b[0;34m(self, fetches, feed_dict, options, run_metadata)\u001b[0m\n\u001b[1;32m    898\u001b[0m     \u001b[0;32mtry\u001b[0m\u001b[0;34m:\u001b[0m\u001b[0;34m\u001b[0m\u001b[0m\n\u001b[1;32m    899\u001b[0m       result = self._run(None, fetches, feed_dict, options_ptr,\n\u001b[0;32m--> 900\u001b[0;31m                          run_metadata_ptr)\n\u001b[0m\u001b[1;32m    901\u001b[0m       \u001b[0;32mif\u001b[0m \u001b[0mrun_metadata\u001b[0m\u001b[0;34m:\u001b[0m\u001b[0;34m\u001b[0m\u001b[0m\n\u001b[1;32m    902\u001b[0m         \u001b[0mproto_data\u001b[0m \u001b[0;34m=\u001b[0m \u001b[0mtf_session\u001b[0m\u001b[0;34m.\u001b[0m\u001b[0mTF_GetBuffer\u001b[0m\u001b[0;34m(\u001b[0m\u001b[0mrun_metadata_ptr\u001b[0m\u001b[0;34m)\u001b[0m\u001b[0;34m\u001b[0m\u001b[0m\n",
      "\u001b[0;32m/usr/local/lib/python3.6/site-packages/tensorflow/python/client/session.py\u001b[0m in \u001b[0;36m_run\u001b[0;34m(self, handle, fetches, feed_dict, options, run_metadata)\u001b[0m\n\u001b[1;32m   1133\u001b[0m     \u001b[0;32mif\u001b[0m \u001b[0mfinal_fetches\u001b[0m \u001b[0;32mor\u001b[0m \u001b[0mfinal_targets\u001b[0m \u001b[0;32mor\u001b[0m \u001b[0;34m(\u001b[0m\u001b[0mhandle\u001b[0m \u001b[0;32mand\u001b[0m \u001b[0mfeed_dict_tensor\u001b[0m\u001b[0;34m)\u001b[0m\u001b[0;34m:\u001b[0m\u001b[0;34m\u001b[0m\u001b[0m\n\u001b[1;32m   1134\u001b[0m       results = self._do_run(handle, final_targets, final_fetches,\n\u001b[0;32m-> 1135\u001b[0;31m                              feed_dict_tensor, options, run_metadata)\n\u001b[0m\u001b[1;32m   1136\u001b[0m     \u001b[0;32melse\u001b[0m\u001b[0;34m:\u001b[0m\u001b[0;34m\u001b[0m\u001b[0m\n\u001b[1;32m   1137\u001b[0m       \u001b[0mresults\u001b[0m \u001b[0;34m=\u001b[0m \u001b[0;34m[\u001b[0m\u001b[0;34m]\u001b[0m\u001b[0;34m\u001b[0m\u001b[0m\n",
      "\u001b[0;32m/usr/local/lib/python3.6/site-packages/tensorflow/python/client/session.py\u001b[0m in \u001b[0;36m_do_run\u001b[0;34m(self, handle, target_list, fetch_list, feed_dict, options, run_metadata)\u001b[0m\n\u001b[1;32m   1314\u001b[0m     \u001b[0;32mif\u001b[0m \u001b[0mhandle\u001b[0m \u001b[0;32mis\u001b[0m \u001b[0;32mNone\u001b[0m\u001b[0;34m:\u001b[0m\u001b[0;34m\u001b[0m\u001b[0m\n\u001b[1;32m   1315\u001b[0m       return self._do_call(_run_fn, feeds, fetches, targets, options,\n\u001b[0;32m-> 1316\u001b[0;31m                            run_metadata)\n\u001b[0m\u001b[1;32m   1317\u001b[0m     \u001b[0;32melse\u001b[0m\u001b[0;34m:\u001b[0m\u001b[0;34m\u001b[0m\u001b[0m\n\u001b[1;32m   1318\u001b[0m       \u001b[0;32mreturn\u001b[0m \u001b[0mself\u001b[0m\u001b[0;34m.\u001b[0m\u001b[0m_do_call\u001b[0m\u001b[0;34m(\u001b[0m\u001b[0m_prun_fn\u001b[0m\u001b[0;34m,\u001b[0m \u001b[0mhandle\u001b[0m\u001b[0;34m,\u001b[0m \u001b[0mfeeds\u001b[0m\u001b[0;34m,\u001b[0m \u001b[0mfetches\u001b[0m\u001b[0;34m)\u001b[0m\u001b[0;34m\u001b[0m\u001b[0m\n",
      "\u001b[0;32m/usr/local/lib/python3.6/site-packages/tensorflow/python/client/session.py\u001b[0m in \u001b[0;36m_do_call\u001b[0;34m(self, fn, *args)\u001b[0m\n\u001b[1;32m   1333\u001b[0m         \u001b[0;32mexcept\u001b[0m \u001b[0mKeyError\u001b[0m\u001b[0;34m:\u001b[0m\u001b[0;34m\u001b[0m\u001b[0m\n\u001b[1;32m   1334\u001b[0m           \u001b[0;32mpass\u001b[0m\u001b[0;34m\u001b[0m\u001b[0m\n\u001b[0;32m-> 1335\u001b[0;31m       \u001b[0;32mraise\u001b[0m \u001b[0mtype\u001b[0m\u001b[0;34m(\u001b[0m\u001b[0me\u001b[0m\u001b[0;34m)\u001b[0m\u001b[0;34m(\u001b[0m\u001b[0mnode_def\u001b[0m\u001b[0;34m,\u001b[0m \u001b[0mop\u001b[0m\u001b[0;34m,\u001b[0m \u001b[0mmessage\u001b[0m\u001b[0;34m)\u001b[0m\u001b[0;34m\u001b[0m\u001b[0m\n\u001b[0m\u001b[1;32m   1336\u001b[0m \u001b[0;34m\u001b[0m\u001b[0m\n\u001b[1;32m   1337\u001b[0m   \u001b[0;32mdef\u001b[0m \u001b[0m_extend_graph\u001b[0m\u001b[0;34m(\u001b[0m\u001b[0mself\u001b[0m\u001b[0;34m)\u001b[0m\u001b[0;34m:\u001b[0m\u001b[0;34m\u001b[0m\u001b[0m\n",
      "\u001b[0;31mNotFoundError\u001b[0m: Key biases not found in checkpoint\n\t [[Node: save_3/RestoreV2 = RestoreV2[dtypes=[DT_FLOAT, DT_FLOAT, DT_FLOAT, DT_FLOAT, DT_FLOAT, DT_FLOAT], _device=\"/job:localhost/replica:0/task:0/device:CPU:0\"](_arg_save_3/Const_0_0, save_3/RestoreV2/tensor_names, save_3/RestoreV2/shape_and_slices)]]\n\nCaused by op 'save_3/RestoreV2', defined at:\n  File \"/usr/local/Cellar/python/3.6.5/Frameworks/Python.framework/Versions/3.6/lib/python3.6/runpy.py\", line 193, in _run_module_as_main\n    \"__main__\", mod_spec)\n  File \"/usr/local/Cellar/python/3.6.5/Frameworks/Python.framework/Versions/3.6/lib/python3.6/runpy.py\", line 85, in _run_code\n    exec(code, run_globals)\n  File \"/usr/local/lib/python3.6/site-packages/ipykernel_launcher.py\", line 16, in <module>\n    app.launch_new_instance()\n  File \"/usr/local/lib/python3.6/site-packages/traitlets/config/application.py\", line 658, in launch_instance\n    app.start()\n  File \"/usr/local/lib/python3.6/site-packages/ipykernel/kernelapp.py\", line 486, in start\n    self.io_loop.start()\n  File \"/usr/local/lib/python3.6/site-packages/tornado/platform/asyncio.py\", line 127, in start\n    self.asyncio_loop.run_forever()\n  File \"/usr/local/Cellar/python/3.6.5/Frameworks/Python.framework/Versions/3.6/lib/python3.6/asyncio/base_events.py\", line 422, in run_forever\n    self._run_once()\n  File \"/usr/local/Cellar/python/3.6.5/Frameworks/Python.framework/Versions/3.6/lib/python3.6/asyncio/base_events.py\", line 1432, in _run_once\n    handle._run()\n  File \"/usr/local/Cellar/python/3.6.5/Frameworks/Python.framework/Versions/3.6/lib/python3.6/asyncio/events.py\", line 145, in _run\n    self._callback(*self._args)\n  File \"/usr/local/lib/python3.6/site-packages/tornado/platform/asyncio.py\", line 117, in _handle_events\n    handler_func(fileobj, events)\n  File \"/usr/local/lib/python3.6/site-packages/tornado/stack_context.py\", line 276, in null_wrapper\n    return fn(*args, **kwargs)\n  File \"/usr/local/lib/python3.6/site-packages/zmq/eventloop/zmqstream.py\", line 450, in _handle_events\n    self._handle_recv()\n  File \"/usr/local/lib/python3.6/site-packages/zmq/eventloop/zmqstream.py\", line 480, in _handle_recv\n    self._run_callback(callback, msg)\n  File \"/usr/local/lib/python3.6/site-packages/zmq/eventloop/zmqstream.py\", line 432, in _run_callback\n    callback(*args, **kwargs)\n  File \"/usr/local/lib/python3.6/site-packages/tornado/stack_context.py\", line 276, in null_wrapper\n    return fn(*args, **kwargs)\n  File \"/usr/local/lib/python3.6/site-packages/ipykernel/kernelbase.py\", line 283, in dispatcher\n    return self.dispatch_shell(stream, msg)\n  File \"/usr/local/lib/python3.6/site-packages/ipykernel/kernelbase.py\", line 233, in dispatch_shell\n    handler(stream, idents, msg)\n  File \"/usr/local/lib/python3.6/site-packages/ipykernel/kernelbase.py\", line 399, in execute_request\n    user_expressions, allow_stdin)\n  File \"/usr/local/lib/python3.6/site-packages/ipykernel/ipkernel.py\", line 208, in do_execute\n    res = shell.run_cell(code, store_history=store_history, silent=silent)\n  File \"/usr/local/lib/python3.6/site-packages/ipykernel/zmqshell.py\", line 537, in run_cell\n    return super(ZMQInteractiveShell, self).run_cell(*args, **kwargs)\n  File \"/usr/local/lib/python3.6/site-packages/IPython/core/interactiveshell.py\", line 2662, in run_cell\n    raw_cell, store_history, silent, shell_futures)\n  File \"/usr/local/lib/python3.6/site-packages/IPython/core/interactiveshell.py\", line 2785, in _run_cell\n    interactivity=interactivity, compiler=compiler, result=result)\n  File \"/usr/local/lib/python3.6/site-packages/IPython/core/interactiveshell.py\", line 2903, in run_ast_nodes\n    if self.run_code(code, result):\n  File \"/usr/local/lib/python3.6/site-packages/IPython/core/interactiveshell.py\", line 2963, in run_code\n    exec(code_obj, self.user_global_ns, self.user_ns)\n  File \"<ipython-input-12-8ef2c2dac44f>\", line 1, in <module>\n    saver = tf.train.Saver()\n  File \"/usr/local/lib/python3.6/site-packages/tensorflow/python/training/saver.py\", line 1284, in __init__\n    self.build()\n  File \"/usr/local/lib/python3.6/site-packages/tensorflow/python/training/saver.py\", line 1296, in build\n    self._build(self._filename, build_save=True, build_restore=True)\n  File \"/usr/local/lib/python3.6/site-packages/tensorflow/python/training/saver.py\", line 1333, in _build\n    build_save=build_save, build_restore=build_restore)\n  File \"/usr/local/lib/python3.6/site-packages/tensorflow/python/training/saver.py\", line 781, in _build_internal\n    restore_sequentially, reshape)\n  File \"/usr/local/lib/python3.6/site-packages/tensorflow/python/training/saver.py\", line 400, in _AddRestoreOps\n    restore_sequentially)\n  File \"/usr/local/lib/python3.6/site-packages/tensorflow/python/training/saver.py\", line 832, in bulk_restore\n    return io_ops.restore_v2(filename_tensor, names, slices, dtypes)\n  File \"/usr/local/lib/python3.6/site-packages/tensorflow/python/ops/gen_io_ops.py\", line 1463, in restore_v2\n    shape_and_slices=shape_and_slices, dtypes=dtypes, name=name)\n  File \"/usr/local/lib/python3.6/site-packages/tensorflow/python/framework/op_def_library.py\", line 787, in _apply_op_helper\n    op_def=op_def)\n  File \"/usr/local/lib/python3.6/site-packages/tensorflow/python/framework/ops.py\", line 3414, in create_op\n    op_def=op_def)\n  File \"/usr/local/lib/python3.6/site-packages/tensorflow/python/framework/ops.py\", line 1740, in __init__\n    self._traceback = self._graph._extract_stack()  # pylint: disable=protected-access\n\nNotFoundError (see above for traceback): Key biases not found in checkpoint\n\t [[Node: save_3/RestoreV2 = RestoreV2[dtypes=[DT_FLOAT, DT_FLOAT, DT_FLOAT, DT_FLOAT, DT_FLOAT, DT_FLOAT], _device=\"/job:localhost/replica:0/task:0/device:CPU:0\"](_arg_save_3/Const_0_0, save_3/RestoreV2/tensor_names, save_3/RestoreV2/shape_and_slices)]]\n"
     ]
    }
   ],
   "source": [
    "saver = tf.train.Saver()\n",
    "with tf.Session() as session:\n",
    "    saver.restore(session,\"my_net/save_net.ckpt\")\n",
    "    print('weights:',session.run(W))\n",
    "    print('biases:',session,run(b))"
   ]
  },
  {
   "cell_type": "code",
   "execution_count": null,
   "metadata": {},
   "outputs": [],
   "source": []
  }
 ],
 "metadata": {
  "kernelspec": {
   "display_name": "Python 3",
   "language": "python",
   "name": "python3"
  },
  "language_info": {
   "codemirror_mode": {
    "name": "ipython",
    "version": 3
   },
   "file_extension": ".py",
   "mimetype": "text/x-python",
   "name": "python",
   "nbconvert_exporter": "python",
   "pygments_lexer": "ipython3",
   "version": "3.6.5"
  }
 },
 "nbformat": 4,
 "nbformat_minor": 2
}
